Workbook

Sheet Test cases
A1: STT | B1: Mã TC | C1: Chức năng | D1: Tên test case | E1: Method | F1: API | G1: Người thực hiện (token) | H1: Dữ liệu đầu vào | I1: HTTP mong đợi | J1: Mã code mong đợi | K1: Kiểm tra thêm | L1: Kết quả thực tế | M1: Trạng thái | N1: Ghi chú
A2: 1 | B2: TC001 | C2: Đăng nhập & token | D2: Đăng nhập sai mật khẩu | E2: POST | F2: /api/auth/login | G2: Không token | H2: {"identifier": "{{principalEmail}}", "password": "sai-mat-khau"} | I2: 401 | J2: 1101 | K2: Tài khoản hoặc mật khẩu không chính xác
A3: 2 | B3: TC002 | C3: Đăng nhập & token | D3: Đăng nhập tài khoản không tồn tại | E3: POST | F3: /api/auth/login | G3: Không token | H3: {"identifier": "khongco@gmail.com", "password": "abc12345"} | I3: 401 | J3: 1101 | K3: Không tiết lộ tài khoản có tồn tại hay không
A4: 3 | B4: TC003 | C4: Đăng nhập & token | D4: Đăng nhập thiếu dữ liệu | E4: POST | F4: /api/auth/login | G4: Không token | H4: {} | I4: 400 | J4: 1000 | K4: Báo lỗi trường identifier
A5: 4 | B5: TC004 | C5: Đăng nhập & token | D5: Hiệu trưởng đăng nhập (mobile) | E5: POST | F5: /api/auth/login | G5: Không token | H5: {"identifier": "{{principalEmail}}", "password": "{{principalPassword}}"} | I5: 200 | J5: 0 | K5: Có accessToken và refreshToken; tokenType = Bearer; Header X-Client-Type: mobile nên token nằm trong body
A6: 5 | B6: TC005 | C6: Đăng nhập & token | D6: Gọi API khi chưa đăng nhập | E6: GET | F6: /api/users/me | G6: Không token | I6: 401 | J6: 1100
A7: 6 | B7: TC006 | C7: Đăng nhập & token | D7: Gọi API với token giả | E7: GET | F7: /api/users/me | G7: Token giả | I7: 401 | J7: 1104
A8: 7 | B8: TC007 | C8: Đăng nhập & token | D8: Xem thông tin tài khoản Hiệu trưởng | E8: GET | F8: /api/users/me | G8: Hiệu trưởng | I8: 200 | J8: 0 | K8: Có role PRINCIPAL; Trạng thái ACTIVE
A9: 8 | B9: TC008 | C9: Đăng nhập & token | D9: Làm mới token (refresh) | E9: POST | F9: /api/auth/refresh-token | G9: Không token | H9: {"refreshToken": "{{principalRefresh}}"} | I9: 200 | J9: 0 | K9: Refresh token mới khác token cũ
A10: 9 | B10: TC009 | C10: Đăng nhập & token | D10: Dùng lại refresh token cũ (đã bị thu hồi) | E10: POST | F10: /api/auth/refresh-token | G10: Không token | H10: {"refreshToken": "{{oldPrincipalRefresh}}"} | I10: 401 | J10: 1104
A11: 10 | B11: TC010 | C11: Đăng nhập & token | D11: Dùng refresh token thay access token | E11: GET | F11: /api/users/me | G11: Refresh token HT | I11: 401 | J11: 0
A12: 11 | B12: TC011 | C12: Quản lý tài khoản | D12: Hiệu trưởng tạo Phó hiệu trưởng | E12: POST | F12: /api/management/staff | G12: Hiệu trưởng | H12: {"email": "{{viceEmail}}", "fullName": "Cô Mai", "password": "vice1234", "role": "VICE_PRINCIPAL"} | I12: 201 | J12: 0 | K12: Role VICE_PRINCIPAL; Bắt đổi mật khẩu lần đầu
A13: 12 | B13: TC012 | C13: Quản lý tài khoản | D13: Phó hiệu trưởng đăng nhập | E13: POST | F13: /api/auth/login | G13: Không token | H13: {"identifier": "{{viceEmail}}", "password": "vice1234"} | I13: 200 | J13: 0 | K13: mustChangePassword = true
A14: 13 | B14: TC013 | C14: Quản lý tài khoản | D14: Phó HT tạo Giáo viên (email viết hoa) | E14: POST | F14: /api/management/staff | G14: Phó hiệu trưởng | H14: {"email": "GV{{runId}}@Gmail.com", "fullName": "Cô Lan", "phoneNumber": "{{teacherPhone}}", "password": "teacher123", "role": "TEACHER"} | I14: 201 | J14: 0 | K14: Email được chuẩn hoá chữ thường
A15: 14 | B15: TC014 | C15: Quản lý tài khoản | D15: Phó HT tạo Nhân viên | E15: POST | F15: /api/management/staff | G15: Phó hiệu trưởng | H15: {"email": "{{staffEmail}}", "fullName": "Chú Bảo", "password": "staff1234", "role": "STAFF"} | I15: 201 | J15: 0 | K15: Role STAFF
A16: 15 | B16: TC015 | C16: Quản lý tài khoản | D16: Phó HT tạo Phó HT khác (không được phép) | E16: POST | F16: /api/management/staff | G16: Phó hiệu trưởng | H16: {"email": "x{{runId}}@gmail.com", "fullName": "X", "password": "vice1234", "role": "VICE_PRINCIPAL"} | I16: 403 | J16: 1103
A17: 16 | B17: TC016 | C17: Quản lý tài khoản | D17: Tạo tài khoản Hiệu trưởng (không được phép) | E17: POST | F17: /api/management/staff | G17: Hiệu trưởng | H17: {"email": "y{{runId}}@gmail.com", "fullName": "Y", "password": "abc12345", "role": "PRINCIPAL"} | I17: 400 | J17: 1207
A18: 17 | B18: TC017 | C18: Quản lý tài khoản | D18: Tạo tài khoản với email đã tồn tại | E18: POST | F18: /api/management/staff | G18: Hiệu trưởng | H18: {"email": "{{teacherEmail}}", "fullName": "Trùng", "password": "abc12345", "role": "TEACHER"} | I18: 409 | J18: 1200
A19: 18 | B19: TC018 | C19: Quản lý tài khoản | D19: Tạo tài khoản với SĐT đã tồn tại | E19: POST | F19: /api/management/staff | G19: Hiệu trưởng | H19: {"email": "z{{runId}}@gmail.com", "fullName": "Trùng", "phoneNumber": "{{teacherPhone}}", "password": "abc12345", "role": "TEACHER"} | I19: 409 | J19: 1201
A20: 19 | B20: TC019 | C20: Quản lý tài khoản | D20: Tạo tài khoản mật khẩu yếu | E20: POST | F20: /api/management/staff | G20: Hiệu trưởng | H20: {"email": "w{{runId}}@gmail.com", "fullName": "W", "password": "123", "role": "TEACHER"} | I20: 400 | J20: 1000 | K20: Báo lỗi trường password
A21: 20 | B21: TC020 | C21: Quản lý tài khoản | D21: Tạo tài khoản email sai định dạng | E21: POST | F21: /api/management/staff | G21: Hiệu trưởng | H21: {"email": "khong-phai-email", "fullName": "W", "password": "abc12345", "role": "TEACHER"} | I21: 400 | J21: 1000 | K21: Báo lỗi trường email
A22: 21 | B22: TC021 | C22: Quản lý tài khoản | D22: Tạo tài khoản thiếu role | E22: POST | F22: /api/management/staff | G22: Hiệu trưởng | H22: {"email": "v{{runId}}@gmail.com", "fullName": "V", "password": "abc12345"} | I22: 400 | J22: 1000 | K22: Báo lỗi trường role
A23: 22 | B23: TC022 | C23: Quản lý tài khoản | D23: Tạo tài khoản role không tồn tại | E23: POST | F23: /api/management/staff | G23: Hiệu trưởng | H23: {"email": "u{{runId}}@gmail.com", "fullName": "U", "password": "abc12345", "role": "ABC"} | I23: 400 | J23: 1001
A24: 23 | B24: TC023 | C24: Quản lý tài khoản | D24: Hiệu trưởng tạo Phó HT thứ 2 | E24: POST | F24: /api/management/staff | G24: Hiệu trưởng | H24: {"email": "{{vice2Email}}", "fullName": "Thầy Nam", "password": "vice1234", "role": "VICE_PRINCIPAL"} | I24: 201 | J24: 0
A25: 24 | B25: TC024 | C25: Quản lý tài khoản | D25: Giáo viên đăng nhập bằng email | E25: POST | F25: /api/auth/login | G25: Không token | H25: {"identifier": "{{teacherEmail}}", "password": "teacher123"} | I25: 200 | J25: 0
A26: 25 | B26: TC025 | C26: Quản lý tài khoản | D26: Giáo viên gọi API quản lý (không được phép) | E26: POST | F26: /api/management/staff | G26: Giáo viên | H26: {"email": "t{{runId}}@gmail.com", "fullName": "T", "password": "abc12345", "role": "TEACHER"} | I26: 403 | J26: 1103
A27: 26 | B27: TC026 | C27: Quản lý tài khoản | D27: Chỉ định tổ trưởng | E27: PUT | F27: /api/management/teachers/{{teacherId}}/head-teacher | G27: Phó hiệu trưởng | I27: 200 | J27: 0 | K27: Có cả TEACHER và HEAD_TEACHER
A28: 27 | B28: TC027 | C28: Quản lý tài khoản | D28: Chỉ định tổ trưởng cho Nhân viên | E28: PUT | F28: /api/management/teachers/{{staffId}}/head-teacher | G28: Phó hiệu trưởng | I28: 404 | J28: 1208
A29: 28 | B29: TC028 | C29: Quản lý tài khoản | D29: Chỉ định tổ trưởng cho id không tồn tại | E29: PUT | F29: /api/management/teachers/999999/head-teacher | G29: Phó hiệu trưởng | I29: 404 | J29: 1208
A30: 29 | B30: TC029 | C30: Quản lý tài khoản | D30: Bỏ chức tổ trưởng | E30: DELETE | F30: /api/management/teachers/{{teacherId}}/head-teacher | G30: Phó hiệu trưởng | I30: 200 | J30: 0 | K30: Không còn HEAD_TEACHER
A31: 30 | B31: TC030 | C31: Quản lý tài khoản | D31: Token cũ của GV bị từ chối sau khi đổi chức vụ | E31: GET | F31: /api/users/me | G31: Giáo viên | I31: 401 | J31: 1104 | K31: Đổi role -> đăng xuất mọi nơi, phải đăng nhập lại
A32: 31 | B32: TC031 | C32: Quản lý tài khoản | D32: Giáo viên đăng nhập lại | E32: POST | F32: /api/auth/login | G32: Không token | H32: {"identifier": "{{teacherEmail}}", "password": "teacher123"} | I32: 200 | J32: 0
A33: 32 | B33: TC032 | C33: Trẻ & ảnh trẻ | D33: Thêm trẻ, tự tạo tài khoản phụ huynh (SĐT +84) | E33: POST | F33: /api/management/children | G33: Phó hiệu trưởng | H33: {"childName": "Bé Na", "dateOfBirth": "2022-05-01", "parentPhone": "{{parentPhoneIntl}}", "parentName": "Chị Hoa"} | I33: 201 | J33: 0 | K33: parentAccountCreated = true; SĐT chuẩn hoá về 0...
A34: 33 | B34: TC033 | C34: Trẻ & ảnh trẻ | D34: Thêm trẻ thứ 2 cùng SĐT phụ huynh | E34: POST | F34: /api/management/children | G34: Hiệu trưởng | H34: {"childName": "Bé Bin", "parentPhone": "{{parentPhone}}", "parentName": "Chị Hoa"} | I34: 201 | J34: 0 | K34: Gắn vào phụ huynh cũ
A35: 34 | B35: TC034 | C35: Trẻ & ảnh trẻ | D35: Thêm trẻ của phụ huynh khác | E35: POST | F35: /api/management/children | G35: Phó hiệu trưởng | H35: {"childName": "Bé Tí", "parentPhone": "{{otherParentPhone}}", "parentName": "Anh Tùng"} | I35: 201 | J35: 0
A36: 35 | B36: TC035 | C36: Trẻ & ảnh trẻ | D36: Thêm trẻ thiếu tên | E36: POST | F36: /api/management/children | G36: Phó hiệu trưởng | H36: {"parentPhone": "{{parentPhone}}", "parentName": "Chị Hoa"} | I36: 400 | J36: 1000 | K36: Báo lỗi childName
A37: 36 | B37: TC036 | C37: Trẻ & ảnh trẻ | D37: Thêm trẻ SĐT phụ huynh sai | E37: POST | F37: /api/management/children | G37: Phó hiệu trưởng | H37: {"childName": "Bé", "parentPhone": "12345", "parentName": "X"} | I37: 400 | J37: 1000 | K37: Báo lỗi parentPhone
A38: 37 | B38: TC037 | C38: Trẻ & ảnh trẻ | D38: Thêm trẻ ngày sinh ở tương lai | E38: POST | F38: /api/management/children | G38: Phó hiệu trưởng | H38: {"childName": "Bé", "dateOfBirth": "2999-01-01", "parentPhone": "{{parentPhone}}", "parentName": "X"} | I38: 400 | J38: 1000 | K38: Báo lỗi dateOfBirth
A39: 38 | B39: TC038 | C39: Trẻ & ảnh trẻ | D39: Giáo viên thêm trẻ (không được phép) | E39: POST | F39: /api/management/children | G39: Giáo viên | H39: {"childName": "Bé", "parentPhone": "{{parentPhone}}", "parentName": "X"} | I39: 403 | J39: 1103
A40: 39 | B40: TC039 | C40: Trẻ & ảnh trẻ | D40: Phụ huynh đăng nhập bằng SĐT, mật khẩu mặc định | E40: POST | F40: /api/auth/login | G40: Không token | H40: {"identifier": "{{parentPhone}}", "password": "{{parentPhone}}"} | I40: 200 | J40: 0 | K40: Bắt đổi mật khẩu
...

Sheet Tổng hợp
A1: Tổng hợp kết quả test
A2: Ô vàng ở sheet 'Test cases' (Kết quả thực tế, Trạng thái, Ghi chú) là ô cần điền; bảng dưới tự tính.
A4: Chức năng | B4: Tổng | C4: Pass | D4: Fail | E4: Blocked | F4: Not run
A5: Đăng nhập & token | B5: =COUNTIF('Test cases'!$C$2:$C$137,A5) | C5: =COUNTIFS('Test cases'!$C$2:$C$137,A5,'Test cases'!$M$2:$M$137,"Pass") | D5: =COUNTIFS('Test cases'!$C$2:$C$137,A5,'Test cases'!$M$2:$M$137,"Fail") | E5: =COUNTIFS('Test cases'!$C$2:$C$137,A5,'Test cases'!$M$2:$M$137,"Blocked") | F5: =B5-C5-D5-E5
A6: Quản lý tài khoản | B6: =COUNTIF('Test cases'!$C$2:$C$137,A6) | C6: =COUNTIFS('Test cases'!$C$2:$C$137,A6,'Test cases'!$M$2:$M$137,"Pass") | D6: =COUNTIFS('Test cases'!$C$2:$C$137,A6,'Test cases'!$M$2:$M$137,"Fail") | E6: =COUNTIFS('Test cases'!$C$2:$C$137,A6,'Test cases'!$M$2:$M$137,"Blocked") | F6: =B6-C6-D6-E6
A7: Trẻ & ảnh trẻ | B7: =COUNTIF('Test cases'!$C$2:$C$137,A7) | C7: =COUNTIFS('Test cases'!$C$2:$C$137,A7,'Test cases'!$M$2:$M$137,"Pass") | D7: =COUNTIFS('Test cases'!$C$2:$C$137,A7,'Test cases'!$M$2:$M$137,"Fail") | E7: =COUNTIFS('Test cases'!$C$2:$C$137,A7,'Test cases'!$M$2:$M$137,"Blocked") | F7: =B7-C7-D7-E7
A8: Mật khẩu | B8: =COUNTIF('Test cases'!$C$2:$C$137,A8) | C8: =COUNTIFS('Test cases'!$C$2:$C$137,A8,'Test cases'!$M$2:$M$137,"Pass") | D8: =COUNTIFS('Test cases'!$C$2:$C$137,A8,'Test cases'!$M$2:$M$137,"Fail") | E8: =COUNTIFS('Test cases'!$C$2:$C$137,A8,'Test cases'!$M$2:$M$137,"Blocked") | F8: =B8-C8-D8-E8
A9: Ảnh của tôi | B9: =COUNTIF('Test cases'!$C$2:$C$137,A9) | C9: =COUNTIFS('Test cases'!$C$2:$C$137,A9,'Test cases'!$M$2:$M$137,"Pass") | D9: =COUNTIFS('Test cases'!$C$2:$C$137,A9,'Test cases'!$M$2:$M$137,"Fail") | E9: =COUNTIFS('Test cases'!$C$2:$C$137,A9,'Test cases'!$M$2:$M$137,"Blocked") | F9: =B9-C9-D9-E9
A10: Người đón trẻ | B10: =COUNTIF('Test cases'!$C$2:$C$137,A10) | C10: =COUNTIFS('Test cases'!$C$2:$C$137,A10,'Test cases'!$M$2:$M$137,"Pass") | D10: =COUNTIFS('Test cases'!$C$2:$C$137,A10,'Test cases'!$M$2:$M$137,"Fail") | E10: =COUNTIFS('Test cases'!$C$2:$C$137,A10,'Test cases'!$M$2:$M$137,"Blocked") | F10: =B10-C10-D10-E10
A11: Khoá tài khoản | B11: =COUNTIF('Test cases'!$C$2:$C$137,A11) | C11: =COUNTIFS('Test cases'!$C$2:$C$137,A11,'Test cases'!$M$2:$M$137,"Pass") | D11: =COUNTIFS('Test cases'!$C$2:$C$137,A11,'Test cases'!$M$2:$M$137,"Fail") | E11: =COUNTIFS('Test cases'!$C$2:$C$137,A11,'Test cases'!$M$2:$M$137,"Blocked") | F11: =B11-C11-D11-E11
A12: Sửa & xoá tài khoản | B12: =COUNTIF('Test cases'!$C$2:$C$137,A12) | C12: =COUNTIFS('Test cases'!$C$2:$C$137,A12,'Test cases'!$M$2:$M$137,"Pass") | D12: =COUNTIFS('Test cases'!$C$2:$C$137,A12,'Test cases'!$M$2:$M$137,"Fail") | E12: =COUNTIFS('Test cases'!$C$2:$C$137,A12,'Test cases'!$M$2:$M$137,"Blocked") | F12: =B12-C12-D12-E12
A13: Quản lý trẻ | B13: =COUNTIF('Test cases'!$C$2:$C$137,A13) | C13: =COUNTIFS('Test cases'!$C$2:$C$137,A13,'Test cases'!$M$2:$M$137,"Pass") | D13: =COUNTIFS('Test cases'!$C$2:$C$137,A13,'Test cases'!$M$2:$M$137,"Fail") | E13: =COUNTIFS('Test cases'!$C$2:$C$137,A13,'Test cases'!$M$2:$M$137,"Blocked") | F13: =B13-C13-D13-E13
A14: Đăng xuất | B14: =COUNTIF('Test cases'!$C$2:$C$137,A14) | C14: =COUNTIFS('Test cases'!$C$2:$C$137,A14,'Test cases'!$M$2:$M$137,"Pass") | D14: =COUNTIFS('Test cases'!$C$2:$C$137,A14,'Test cases'!$M$2:$M$137,"Fail") | E14: =COUNTIFS('Test cases'!$C$2:$C$137,A14,'Test cases'!$M$2:$M$137,"Blocked") | F14: =B14-C14-D14-E14
A15: Tổng | B15: =SUM(B5:B14) | C15: =SUM(C5:C14) | D15: =SUM(D5:D14) | E15: =SUM(E5:E14) | F15: =SUM(F5:F14)
A16: Tỉ lệ Pass | C16: =IF(B15=0,0,C15/B15)

Sheet Tài khoản & dữ liệu
A1: Thông tin | B1: Giá trị
A2: Base URL | B2: http://localhost:8080
A3: Hiệu trưởng | B3: admin@carenest.com / Admin@123 (tạo sẵn khi start app)
A4: Phó hiệu trưởng | B4: pho<runId>@gmail.com / vice1234 (TC tạo)
A5: Giáo viên | B5: gv<runId>@gmail.com / teacher123 (TC tạo)
A6: Nhân viên | B6: nv<runId>@gmail.com / staff1234 (TC tạo)
A7: Phụ huynh | B7: 09<runId> / mật khẩu mặc định = SĐT (TC tạo khi thêm trẻ)
A8: runId | B8: 8 số cuối của thời điểm chạy, sinh ở TC001 để mỗi lần chạy không trùng dữ liệu
A9: File mẫu | B9: postman/sample.png (ảnh hợp lệ), postman/not-image.png (không phải ảnh)
A10: Header mobile | B10: X-Client-Type: mobile -> token trả trong body; không có header -> token trong cookie (web)

Sheet Mã lỗi
A1: Code | B1: HTTP | C1: Ý nghĩa
A2: 0 | B2: 200 | C2: Thành công
A3: 1000 | B3: 400 | C3: Dữ liệu không hợp lệ (data chứa lỗi từng trường)
A4: 1001 | B4: 400 | C4: Dữ liệu sai định dạng (JSON hỏng, enum sai)
A5: 415 | B5: 415 | C5: Sai Content-Type, cần multipart/form-data (format GlobalExceptionHandler: {code, desc, data})
A6: 1100 | B6: 401 | C6: Chưa đăng nhập
A7: 1101 | B7: 401 | C7: Sai tài khoản hoặc mật khẩu
A8: 1102 | B8: 403 | C8: Tài khoản đã bị khoá
A9: 1103 | B9: 403 | C9: Không có quyền
A10: 1104 | B10: 401 | C10: Token không hợp lệ / hết hạn / đã thu hồi
A11: 1200 | B11: 409 | C11: Email đã được sử dụng
A12: 1201 | B12: 409 | C12: SĐT đã được sử dụng
A13: 1202 | B13: 400 | C13: Xác nhận mật khẩu không khớp
... A32: 1501 | B32: 404 | C32: Người đón không tồn tại
